<?xml version="1.0" encoding="utf-8"?>
<robot name="mobile">
  <!-- http://wiki.ros.org/simulator_gazebo/Tutorials/ListOfMaterials -->
  <gazebo reference="BaseLink">
    <kp value="100000.0"/>
    <kd value="1.0"/>
    <mu1>0.1</mu1>
    <mu2>0.1</mu2>
    <self_collide>0</self_collide>
  </gazebo>
  <gazebo reference="ArmBase">
    <kp value="100000.0"/>
    <kd value="10.0"/>
    <mu1>0.1</mu1>
    <mu2>0.1</mu2>
    <self_collide>0</self_collide>
    <material>Gazebo/Yellow</material>
  </gazebo>
  <gazebo reference="DriWheel_R">
    <kp value="1000000.0"/>
    <kd value="10.0"/>
    <mu1>0.8</mu1>
    <mu2>0.8</mu2>
    <material>Gazebo/Blue</material>
  </gazebo>
  <gazebo reference="DriWheel_L">
    <kp value="1000000.0"/>
    <kd value="10.0"/>
    <mu1>0.8</mu1>
    <mu2>0.8</mu2>
    <material>Gazebo/Blue</material>
  </gazebo>
  <!-- kp越大，轮子越容易漂移 -->
  <gazebo reference="UniWheel_LF">
    <kp value="2000000.0"/>
    <kd value="1.0"/>
    <mu1>0.8</mu1>
    <mu2>0.8</mu2>
    <material>Gazebo/BlueTransparent</material>
  </gazebo>
  <gazebo reference="UniWheel_RF">
    <kp value="2000000.0"/>
    <kd value="1.0"/>
    <mu1>0.8</mu1>
    <mu2>0.8</mu2>
    <material>Gazebo/BlueTransparent</material>
  </gazebo>
  <gazebo reference="UniWheel_LB">
    <kp value="2000000.0"/>
    <kd value="1.0"/>
    <mu1>0.8</mu1>
    <mu2>0.8</mu2>
    <material>Gazebo/BlueTransparent</material>
  </gazebo>
  <gazebo reference="UniWheel_RB">
    <kp value="2000000.0"/>
    <kd value="1.0"/>
    <mu1>0.8</mu1>
    <mu2>0.8</mu2>
    <material>Gazebo/BlueTransparent</material>
  </gazebo>
  <gazebo reference="Head">
    <kp value="100000.0"/>
    <kd value="1.0"/>
    <mu1>0.1</mu1>
    <mu2>0.1</mu2>
    <material>Gazebo/RedBright</material>
  </gazebo>
  <gazebo reference="Radar_2D">
    <kp value="100000.0"/>
    <kd value="1.0"/>
    <mu1>0.1</mu1>
    <mu2>0.1</mu2>
    <material>Gazebo/DarkGrey</material>
  </gazebo>
  <gazebo reference="VisualWheel_L">
    <material>Gazebo/Red</material>
  </gazebo>
  <gazebo reference="VisualWheel_R">
    <material>Gazebo/Yellow</material>
  </gazebo>
  <gazebo reference="j2s7s300_link_base">
    <material>Gazebo/Grey</material>
  </gazebo>
  <gazebo reference="j2s7s300_link_1">
    <material>Gazebo/Grey</material>
  </gazebo>
  <gazebo reference="j2s7s300_link_2">
    <material>Gazebo/Grey</material>
  </gazebo>
  <gazebo reference="j2s7s300_link_3">
    <material>Gazebo/Grey</material>
  </gazebo>
  <gazebo reference="j2s7s300_link_4">
    <material>Gazebo/Grey</material>
  </gazebo>
  <gazebo reference="j2s7s300_link_5">
    <material>Gazebo/Grey</material>
  </gazebo>
  <gazebo reference="j2s7s300_link_6">
    <material>Gazebo/Grey</material>
  </gazebo>
  <gazebo reference="j2s7s300_link_7">
    <material>Gazebo/Grey</material>
  </gazebo>
  <gazebo reference="j2s7s300_end_effector">
    <material>Gazebo/GreenTransparent</material>
  </gazebo>

  <link name="FloatTX"> </link>
  <link name="FloatTY"> </link>
  <link name="FloatRZ"> </link>
  <joint name="JT_FloatTX" type="prismatic">
    <origin
      xyz="0 0 0"
      rpy="0 0 0" />
    <parent
      link="FloatTX" />
    <child
      link="FloatTY" />
    <axis
      xyz="1 0 0" />
    <limit
      lower="-100000000000000"
      upper="100000000000000"
      effort="100"
      velocity="30" />
  </joint>
  <joint name="JT_FloatTY" type="prismatic">
    <origin
      xyz="0 0 0"
      rpy="0 0 0" />
    <parent
      link="FloatTY" />
    <child
      link="FloatRZ" />
    <axis
      xyz="0 1 0" />
    <limit
      lower="-100000000000000"
      upper="100000000000000"
      effort="100"
      velocity="30" />
  </joint>
  <joint name="JT_FloatRZ" type="revolute">
    <origin
      xyz="0 0 0"
      rpy="0 0 0" />
    <parent
      link="FloatRZ" />
    <child
      link="BaseLink" />
    <axis
      xyz="0 0 1" />
    <limit
      lower="-100000000000000"
      upper="100000000000000"
      effort="100"
      velocity="30" />
  </joint>
  <link name="BaseLink">
    <inertial>
      <origin
        xyz="-0.0697248975605124 9.35986032828009E-05 0.186131310444443"
        rpy="0 0 0" />
      <mass
        value="64.9999523677222" />
      <inertia
        ixx="1.35069488959022"
        ixy="0.000479754719690234"
        ixz="1.48197273533961E-06"
        iyy="0.963094057696194"
        iyz="-7.03349014736132E-06"
        izz="1.34062606564175" />
    </inertial>
    <visual>
      <origin
        xyz="0 0 0"
        rpy="0 0 0" />
      <geometry>
        <mesh
          filename="package://mobile_base_urdf/model/base/v3/meshes/BaseLink.STL" />
      </geometry>
      <material
        name="">
        <color
          rgba="0.752941176470588 0.752941176470588 0.752941176470588 1" />
      </material>
    </visual>
    <collision>
      <origin rpy="0 0 0" xyz="0 0 0.025"/>
      <geometry>
        <box size="0.5 0.14 0.15"/>
      </geometry>
    </collision>
  </link>
  <link
    name="ArmBase">
    <inertial>
      <origin
        xyz="-0.0272741114005057 0.00094394189111098 -0.0308551972687778"
        rpy="0 0 0" />
      <mass
        value="0.713162476928904" />
      <inertia
        ixx="0.00220534830451126"
        ixy="8.35547600892114E-07"
        ixz="-6.18305224606399E-05"
        iyy="0.00152386550417795"
        iyz="1.06604349141974E-06"
        izz="0.000996301117911694" />
    </inertial>
    <visual>
      <origin
        xyz="0 0 0"
        rpy="3.141592653589793 0 0" />
      <geometry>
        <mesh
          filename="package://mobile_base_urdf/model/base/v3/meshes/ArmBase.STL" />
      </geometry>
      <material
        name="">
        <color
          rgba="0.752941176470588 0.752941176470588 0.752941176470588 1" />
      </material>
    </visual>
  </link>
  <joint
    name="JT_ArmBase"
    type="prismatic">
    <origin
      xyz="0.034 -0.001 0.276"
      rpy="0 0 0" />
    <parent
      link="BaseLink" />
    <child
      link="ArmBase" />
    <axis
      xyz="0 0 1" />
    <limit
      lower="0"
      upper="0.49"
      effort="1000"
      velocity="0.06" />
  </joint>
  <link
    name="Radar_2D">
    <inertial>
      <origin
        xyz="8.22216969754708E-05 0.0195154420160331 3.427162408858E-09"
        rpy="0 0 0" />
      <mass
        value="0.102883853456169" />
      <inertia
        ixx="3.66225482144748E-05"
        ixy="1.0587412031796E-07"
        ixz="-3.58548249909878E-12"
        iyy="4.69758377443588E-05"
        iyz="-6.02604694180553E-13"
        izz="3.69805831442243E-05" />
    </inertial>
    <visual>
      <origin
        xyz="0 0 0"
        rpy="0 0 0" />
      <geometry>
        <mesh
          filename="package://mobile_base_urdf/model/base/v3/meshes/Radar_2D.STL" />
      </geometry>
      <material
        name="">
        <color
          rgba="0.752941176470588 0.752941176470588 0.752941176470588 1" />
      </material>
    </visual>
  </link>
  <joint
    name="JT_Radar_2D"
    type="fixed">
    <origin
      xyz="0.213 0 0.0905"
      rpy="1.5708 0 3.1416" />
    <parent
      link="BaseLink" />
    <child
      link="Radar_2D" />
    <axis
      xyz="0 0 0" />
  </joint>
  <link
    name="Pantilt_PanLink">
    <inertial>
      <origin
        xyz="2.18543483591707E-12 9.36750677027476E-17 0.022419493625198"
        rpy="0 0 0" />
      <mass
        value="0.125638006386443" />
      <inertia
        ixx="5.7984036976015E-05"
        ixy="-4.95095367264507E-09"
        ixz="1.26449088862416E-16"
        iyy="0.000158965664023198"
        iyz="9.95930618769165E-20"
        izz="0.000150893790612493" />
    </inertial>
    <visual>
      <origin
        xyz="0 0 0"
        rpy="0 0 0" />
      <geometry>
        <mesh
          filename="package://mobile_base_urdf/model/base/v3/meshes/Pantilt_PanLink.STL" />
      </geometry>
      <material
        name="">
        <color
          rgba="0.796078431372549 0.823529411764706 0.937254901960784 1" />
      </material>
    </visual>
  </link>
  <joint
    name="JT_Pantilt_PanLink"
    type="fixed">
    <origin
      xyz="-0.021 0 1.0081"
      rpy="0 0 -1.5708" />
    <parent
      link="BaseLink" />
    <child
      link="Pantilt_PanLink" />
    <axis
      xyz="0 0 1" />
  </joint>
  <link
    name="Pantilt_TiltLink">
    <inertial>
      <origin
        xyz="-2.25379299249759E-12 0.031479884333478 1.20049803431499E-13"
        rpy="0 0 0" />
      <mass
        value="0.119003363420873" />
      <inertia
        ixx="7.90464190146043E-05"
        ixy="-3.79029998872968E-16"
        ixz="7.60779981349867E-19"
        iyy="0.00035798448028944"
        iyz="2.37471710121675E-16"
        izz="0.00028284413383159" />
    </inertial>
    <visual>
      <origin
        xyz="0 0 0"
        rpy="0 0 0" />
      <geometry>
        <mesh
          filename="package://mobile_base_urdf/model/base/v3/meshes/Pantilt_TiltLink.STL" />
      </geometry>
      <material
        name="">
        <color
          rgba="0.796078431372549 0.823529411764706 0.937254901960784 1" />
      </material>
    </visual>
  </link>
  <joint
    name="JT_Pantilt_TiltLink"
    type="fixed">
    <origin
      xyz="0 0.00025 0.0413"
      rpy="1.5708 0 3.1416" />
    <parent
      link="Pantilt_PanLink" />
    <child
      link="Pantilt_TiltLink" />
    <axis
      xyz="1 0 0" />
  </joint>
  <link
    name="Head">
    <inertial>
      <origin
        xyz="7.01161821037004E-06 -0.00244242053568144 -0.0752179075942135"
        rpy="0 0 0" />
      <mass
        value="0.398951454797707" />
      <inertia
        ixx="0.000860013559453623"
        ixy="-2.53668430914557E-08"
        ixz="1.00973665605483E-07"
        iyy="0.0018274751159565"
        iyz="5.23242580668497E-06"
        izz="0.0012846248952368" />
    </inertial>
    <visual>
      <origin
        xyz="0 -0.0121 0"
        rpy="0 0 0" />
      <geometry>
        <mesh
          filename="package://mobile_base_urdf/model/base/v3/meshes/Head.STL" />
      </geometry>
      <material
        name="">
        <color
          rgba="0.752941176470588 0.752941176470588 0.752941176470588 1" />
      </material>
    </visual>
  </link>
  <joint
    name="JT_Head"
    type="fixed">
    <origin
      xyz="0 0.0705 0.0795"
      rpy="0 0 0" />
    <parent
      link="Pantilt_TiltLink" />
    <child
      link="Head" />
    <axis
      xyz="0 0 0" />
  </joint>
  <link
    name="UniWheelBase_LF">
    <inertial>
      <origin
        xyz="-9.15933995315754E-16 0.0182260960322876 -0.0642291000155078"
        rpy="0 0 0" />
      <mass
        value="0.0847351495375798" />
      <inertia
        ixx="6.07135705376024E-05"
        ixy="1.38064990757287E-18"
        ixz="-6.23412902781099E-19"
        iyy="3.49474283390521E-05"
        iyz="1.16340041790674E-05"
        izz="3.34756139191197E-05" />
    </inertial>
    <visual>
      <origin
        xyz="0 0 0"
        rpy="0 0 0" />
      <geometry>
        <mesh
          filename="package://mobile_base_urdf/model/base/v3/meshes/UniWheelBase_LF.STL" />
      </geometry>
      <material
        name="">
        <color
          rgba="0.752941176470588 0.752941176470588 0.752941176470588 1" />
      </material>
    </visual>
  </link>
  <joint
    name="JT_UniWheelBase_LF"
    type="fixed">
    <origin
      xyz="0.2 0.1435 0.031"
      rpy="0 0 1.5708" />
    <parent
      link="BaseLink" />
    <child
      link="UniWheelBase_LF" />
    <axis
      xyz="0 0 1" />
  </joint>
  <link
    name="UniWheel_LF">
    <inertial>
      <origin
        xyz="3.81426298323717E-08 -2.14332611103707E-08 -1.63217898571655E-08"
        rpy="0 0 0" />
      <mass
        value="0.131455385710739" />
      <inertia
        ixx="4.67614248550029E-05"
        ixy="2.92736299371043E-11"
        ixz="-4.25507933450125E-11"
        iyy="8.85134139088376E-05"
        iyz="-1.15416488880503E-11"
        izz="4.6763063659093E-05" />
    </inertial>
    <visual>
      <origin
        xyz="0 0 0"
        rpy="0 0 0" />
      <geometry>
        <mesh
          filename="package://mobile_base_urdf/model/base/v3/meshes/UniWheel_LF.STL" />
      </geometry>
      <material
        name="">
        <color
          rgba="0.752941176470588 0.752941176470588 0.752941176470588 1" />
      </material>
    </visual>
    <collision>
      <origin
        xyz="0 0 0"
        rpy="1.57079632679489661923 0 0" />
      <geometry>
        <cylinder length="0.0001" radius="0.0375" />
      </geometry>
    </collision>
  </link>
  <joint
    name="JT_UniWheel_LF"
    type="fixed">
    <origin
      xyz="0 0.024 -0.0775"
      rpy="0 -0.11262 1.5708" />
    <parent
      link="UniWheelBase_LF" />
    <child
      link="UniWheel_LF" />
    <axis
      xyz="0 1 0" />
  </joint>
  <link
    name="UniWheelBase_RB">
    <inertial>
      <origin
        xyz="-9.71445146547012E-16 0.0182260960322876 -0.0642291000155078"
        rpy="0 0 0" />
      <mass
        value="0.0847351495375797" />
      <inertia
        ixx="6.07135705376023E-05"
        ixy="1.38866328531335E-18"
        ixz="-6.29343822979503E-19"
        iyy="3.4947428339052E-05"
        iyz="1.16340041790674E-05"
        izz="3.34756139191196E-05" />
    </inertial>
    <visual>
      <origin
        xyz="0 0 0"
        rpy="0 0 0" />
      <geometry>
        <mesh
          filename="package://mobile_base_urdf/model/base/v3/meshes/UniWheelBase_RB.STL" />
      </geometry>
      <material
        name="">
        <color
          rgba="0.752941176470588 0.752941176470588 0.752941176470588 1" />
      </material>
    </visual>
  </link>
  <joint
    name="JT_UniWheelBase_RB"
    type="fixed">
    <origin
      xyz="-0.2 -0.1435 0.031"
      rpy="0 0 1.5708" />
    <parent
      link="BaseLink" />
    <child
      link="UniWheelBase_RB" />
    <axis
      xyz="0 0 1" />
  </joint>
  <link
    name="UniWheel_RB">
    <inertial>
      <origin
        xyz="3.8142629943394E-08 -2.14332609993484E-08 -1.63217898641044E-08"
        rpy="0 0 0" />
      <mass
        value="0.131455385710739" />
      <inertia
        ixx="4.67614248550025E-05"
        ixy="2.92736298794068E-11"
        ixz="-4.25507933484007E-11"
        iyy="8.85134139088377E-05"
        iyz="-1.15416488244326E-11"
        izz="4.67630636590926E-05" />
    </inertial>
    <visual>
      <origin
        xyz="0 0 0"
        rpy="0 0 0" />
      <geometry>
        <mesh
          filename="package://mobile_base_urdf/model/base/v3/meshes/UniWheel_RB.STL" />
      </geometry>
      <material
        name="">
        <color
          rgba="0.752941176470588 0.752941176470588 0.752941176470588 1" />
      </material>
    </visual>
    <collision>
      <origin
        xyz="0 0 0"
        rpy="1.57079632679489661923 0 0" />
      <geometry>
        <cylinder length="0.0001" radius="0.0375" />
      </geometry>
    </collision>
  </link>
  <joint
    name="JT_UniWheel_RB"
    type="fixed">
    <origin
      xyz="0 0.024 -0.0775"
      rpy="0 -0.11262 1.5708" />
    <parent
      link="UniWheelBase_RB" />
    <child
      link="UniWheel_RB" />
    <axis
      xyz="0 1 0" />
  </joint>
  <link
    name="UniWheelBase_RF">
    <inertial>
      <origin
        xyz="-9.15933995315754E-16 0.0182260960322876 -0.0642291000155078"
        rpy="0 0 0" />
      <mass
        value="0.0847351495375797" />
      <inertia
        ixx="6.07135705376022E-05"
        ixy="1.3856374474727E-18"
        ixz="-6.2925381710409E-19"
        iyy="3.4947428339052E-05"
        iyz="1.16340041790674E-05"
        izz="3.34756139191196E-05" />
    </inertial>
    <visual>
      <origin
        xyz="0 0 0"
        rpy="0 0 0" />
      <geometry>
        <mesh
          filename="package://mobile_base_urdf/model/base/v3/meshes/UniWheelBase_RF.STL" />
      </geometry>
      <material
        name="">
        <color
          rgba="0.752941176470588 0.752941176470588 0.752941176470588 1" />
      </material>
    </visual>
  </link>
  <joint
    name="JT_UniWheelBase_RF"
    type="fixed">
    <origin
      xyz="0.2 -0.1435 0.031"
      rpy="0 0 1.5708" />
    <parent
      link="BaseLink" />
    <child
      link="UniWheelBase_RF" />
    <axis
      xyz="0 0 1" />
  </joint>
  <link
    name="UniWheel_RF">
    <inertial>
      <origin
        xyz="3.81426298323717E-08 -2.14332610826151E-08 -1.63217898641044E-08"
        rpy="0 0 0" />
      <mass
        value="0.131455385710739" />
      <inertia
        ixx="4.67614248550028E-05"
        ixy="2.92736299627237E-11"
        ixz="-4.25507933403539E-11"
        iyy="8.85134139088377E-05"
        iyz="-1.15416488470831E-11"
        izz="4.67630636590929E-05" />
    </inertial>
    <visual>
      <origin
        xyz="0 0 0"
        rpy="0 0 0" />
      <geometry>
        <mesh
          filename="package://mobile_base_urdf/model/base/v3/meshes/UniWheel_RF.STL" />
      </geometry>
      <material
        name="">
        <color
          rgba="0.752941176470588 0.752941176470588 0.752941176470588 1" />
      </material>
    </visual>
    <collision>
      <origin
        xyz="0 0 0"
        rpy="1.57079632679489661923 0 0" />
      <geometry>
        <cylinder length="0.0001" radius="0.0375" />
      </geometry>
    </collision>
  </link>
  <joint
    name="JT_UniWheel_RF"
    type="fixed">
    <origin
      xyz="0 0.024 -0.0775"
      rpy="0 -0.11262 1.5708" />
    <parent
      link="UniWheelBase_RF" />
    <child
      link="UniWheel_RF" />
    <axis
      xyz="0 1 0" />
  </joint>
  <link
    name="UniWheelBase_LB">
    <inertial>
      <origin
        xyz="2.77555756156289E-17 0.0182260960322876 -0.0642291000155078"
        rpy="0 0 0" />
      <mass
        value="0.0847351495375797" />
      <inertia
        ixx="6.07135705376023E-05"
        ixy="3.39738839740087E-20"
        ixz="-1.64218142542497E-20"
        iyy="3.4947428339052E-05"
        iyz="1.16340041790674E-05"
        izz="3.34756139191196E-05" />
    </inertial>
    <visual>
      <origin
        xyz="0 0 0"
        rpy="0 0 0" />
      <geometry>
        <mesh
          filename="package://mobile_base_urdf/model/base/v3/meshes/UniWheelBase_LB.STL" />
      </geometry>
      <material
        name="">
        <color
          rgba="0.752941176470588 0.752941176470588 0.752941176470588 1" />
      </material>
    </visual>
  </link>
  <joint
    name="JT_UniWheelBase_LB"
    type="fixed">
    <origin
      xyz="-0.2 0.1435 0.031"
      rpy="0 0 1.5708" />
    <parent
      link="BaseLink" />
    <child
      link="UniWheelBase_LB" />
    <axis
      xyz="0 0 1" />
  </joint>
  <link
    name="UniWheel_LB">
    <inertial>
      <origin
        xyz="3.81426298601273E-08 -2.14332609993484E-08 -1.63217898502266E-08"
        rpy="0 0 0" />
      <mass
        value="0.131455385710739" />
      <inertia
        ixx="4.67614248550029E-05"
        ixy="2.92736298697553E-11"
        ixz="-4.25507933407774E-11"
        iyy="8.85134139088378E-05"
        iyz="-1.15416488421917E-11"
        izz="4.6763063659093E-05" />
    </inertial>
    <visual>
      <origin
        xyz="0 0 0"
        rpy="0 0 0" />
      <geometry>
        <mesh
          filename="package://mobile_base_urdf/model/base/v3/meshes/UniWheel_LB.STL" />
      </geometry>
      <material
        name="">
        <color
          rgba="0.752941176470588 0.752941176470588 0.752941176470588 1" />
      </material>
    </visual>
    <collision>
      <origin
        xyz="0 0 0"
        rpy="1.57079632679489661923 0 0" />
      <geometry>
        <cylinder length="0.0001" radius="0.0375" />
      </geometry>
    </collision>
  </link>
  <joint
    name="JT_UniWheel_LB"
    type="fixed">
    <origin
      xyz="0 0.024 -0.0775"
      rpy="0 -0.11262 1.5708" />
    <parent
      link="UniWheelBase_LB" />
    <child
      link="UniWheel_LB" />
    <axis
      xyz="0 1 0" />
  </joint>
  <link
    name="DriWheel_L">
    <inertial>
      <origin
        xyz="0 0 0"
        rpy="0 0 0" />
      <mass
        value="0.55025375587753" />
      <inertia
        ixx="0.00101587186790134"
        ixy="-1.42117906446844E-09"
        ixz="2.42189453861389E-09"
        iyy="0.000590551548666396"
        iyz="8.57135076871467E-09"
        izz="0.000590534709673099" />
    </inertial>
    <visual>
      <origin
        xyz="0 -0.028350 0"
        rpy="1.5708 0 1.5708" />
      <geometry>
        <mesh
          filename="package://mobile_base_urdf/model/base/v3/meshes/DriWheel_L.STL" />
      </geometry>
      <material
        name="">
        <color
          rgba="0.752941176470588 0.752941176470588 0.752941176470588 1" />
      </material>
    </visual>
    <collision>
      <origin rpy="1.57079632679489661923 0 0" xyz="0 0 0"/>
      <geometry>
        <cylinder length="0.0001" radius="0.084"/>
      </geometry>
    </collision>
  </link>
  <joint
    name="JT_DriWheel_L"
    type="continuous">
    <origin
      xyz="0 0.19945 0"
      rpy="0 0 0" />
    <parent
      link="BaseLink" />
    <child
      link="DriWheel_L" />
    <axis
      xyz="0 1 0" />
    <limit
      lower="-1000000000000"
      upper="1000000000000"
      effort="1000"
      velocity="30" />
    <dynamics damping="0.01" friction="0.001"/>
  </joint>
  <link
    name="DriWheel_R">
    <inertial>
      <origin
        xyz="0 0 0"
        rpy="0 0 0" />
      <mass
        value="0.550253755877532" />
      <inertia
        ixx="0.00101587186790135"
        ixy="1.42117906464977E-09"
        ixz="2.42189453862527E-09"
        iyy="0.000590551548666399"
        iyz="-8.57135076864949E-09"
        izz="0.000590534709673102" />
    </inertial>
    <visual>
      <origin
        xyz="0 0.028350 0"
        rpy="1.5708 0 1.5708" />
      <geometry>
        <mesh
          filename="package://mobile_base_urdf/model/base/v3/meshes/DriWheel_R.STL" />
      </geometry>
      <material
        name="">
        <color
          rgba="0.752941176470588 0.752941176470588 0.752941176470588 1" />
      </material>
    </visual>
    <collision>
      <origin rpy="1.57079632679489661923 0 0" xyz="0 0 0"/>
      <geometry>
        <cylinder length="0.0001" radius="0.084"/>
      </geometry>
    </collision>
  </link>
  <joint
    name="JT_DriWheel_R"
    type="continuous">
    <origin
      xyz="0 -0.19945 0"
      rpy="0 0 0" />
    <parent
      link="BaseLink" />
    <child
      link="DriWheel_R" />
    <axis
      xyz="0 1 0" />
    <limit
      lower="-1000000000000"
      upper="1000000000000"
      effort="1000"
      velocity="30" />
    <dynamics damping="0.01" friction="0.001"/>
  </joint>
  <link name="VisualWheel_L">
    <visual>
      <origin xyz="0 0.024 0" rpy="0 0 0" />
      <geometry>
        <box size="0.01 0.001 0.15"/>
      </geometry>
    </visual>
  </link>
  <joint name="JT_VisualWheel_L"
    type="fixed">
    <origin
      xyz="0 0 0"
      rpy="0 0 0" />
    <parent
      link="DriWheel_L" />
    <child
      link="VisualWheel_L" />
  </joint>
  <link name="VisualWheel_R">
    <visual>
      <origin xyz="0 -0.024 0" rpy="0 0 0" />
      <geometry>
        <box size="0.01 0.001 0.15"/>
      </geometry>
    </visual>
  </link>
  <joint name="JT_VisualWheel_R"
    type="fixed">
    <origin
      xyz="0 0 0"
      rpy="0 0 0" />
    <parent
      link="DriWheel_R" />
    <child
      link="VisualWheel_R" />
  </joint>

    <link name="j2s7s300_link_base">
    <visual>
      <geometry>
        <mesh filename="package://mobile_base_urdf/model/arm/kinova/meshes/base.dae"/>
      </geometry>
      <material name="carbon_fiber">
        <color rgba="0.792156862745098 0.819607843137255 0.933333333333333 1"/>
      </material>
    </visual>
    <inertial>
      <mass value="0.46784"/>
      <origin rpy="0 0 0" xyz="0 0 0.1255"/>
      <inertia ixx="0.000951270861568" ixy="0" ixz="0" iyy="0.000951270861568" iyz="0" izz="0.000374272"/>
    </inertial>
  </link>
  <joint name="j2s7s300_joint_base" type="fixed">
    <parent link="ArmBase"/>
    <child link="j2s7s300_link_base"/>
    <axis xyz="0 0 0"/>
    <limit effort="50" lower="0" upper="0" velocity="30"/>
    <origin rpy="0 1.57079632679489661923 0" xyz="0 0 0"/>
    <dynamics damping=".2" friction=".0"/>
  </joint>
  <link name="j2s7s300_link_1">
    <visual>
      <geometry>
        <mesh filename="package://mobile_base_urdf/model/arm/kinova/meshes/shoulder.dae"/>
      </geometry>
      <material name="carbon_fiber">
        <color rgba="0.792156862745098 0.819607843137255 0.933333333333333 1"/>
      </material>
    </visual>
    <visual>
      <geometry>
        <mesh filename="package://mobile_base_urdf/model/arm/kinova/meshes/ring_big.STL"/>
      </geometry>
    </visual>
    <inertial>
      <mass value="0.7477"/>
      <origin xyz="0 -0.002 -0.0605"/>
      <inertia ixx="0.00152031725204" ixy="0" ixz="0" iyy="0.00152031725204" iyz="0" izz="0.00059816"/>
    </inertial>
  </link>
  <joint name="j2s7s300_joint_1" type="continuous">
    <parent link="j2s7s300_link_base"/>
    <child link="j2s7s300_link_1"/>
    <axis xyz="0 0 1"/>
    <limit effort="50" lower="-6.28318530718" upper="6.28318530718" velocity="30"/>
    <origin rpy="0 3.14159265358979323846 0" xyz="0 0 0.15675"/>
    <dynamics damping=".2" friction=".0"/>
  </joint>
  <transmission name="j2s7s300_joint_1_trans">
    <type>transmission_interface/SimpleTransmission</type>
    <joint name="j2s7s300_joint_1">
      <hardwareInterface>hardware_interface/EffortJointInterface</hardwareInterface>
    </joint>
    <actuator name="j2s7s300_joint_1_actuator">
      <hardwareInterface>hardware_interface/EffortJointInterface</hardwareInterface>
      <mechanicalReduction>160</mechanicalReduction>
    </actuator>
  </transmission>
  <link name="j2s7s300_link_2">
    <visual>
      <geometry>
        <mesh filename="package://mobile_base_urdf/model/arm/kinova/meshes/arm_half_1.dae"/>
      </geometry>
      <material name="carbon_fiber">
        <color rgba="0.792156862745098 0.819607843137255 0.933333333333333 1"/>
      </material>
    </visual>
    <visual>
      <geometry>
        <mesh filename="package://mobile_base_urdf/model/arm/kinova/meshes/ring_big.STL"/>
      </geometry>
    </visual>
    <collision>
      <geometry>
        <mesh filename="package://mobile_base_urdf/model/arm/kinova/meshes/arm_half_1.dae"/>
      </geometry>
    </collision>
    <inertial>
      <mass value="0.8447"/>
      <origin xyz="0 -0.103563213 0"/>
      <inertia ixx="0.00247073761701" ixy="0" ixz="0" iyy="0.000380115" iyz="0" izz="0.00247073761701"/>
    </inertial>
  </link>
  <joint name="j2s7s300_joint_2" type="revolute">
    <parent link="j2s7s300_link_1"/>
    <child link="j2s7s300_link_2"/>
    <axis xyz="0 0 1"/>
    <limit effort="50" lower="0.820304748437" upper="5.46288055874" velocity="30"/>
    <origin rpy="-1.57079632679489661923 0 3.14159265358979323846" xyz="0 0.0016 -0.11875"/>
    <dynamics damping=".2" friction=".0"/>
  </joint>
  <transmission name="j2s7s300_joint_2_trans">
    <type>transmission_interface/SimpleTransmission</type>
    <joint name="j2s7s300_joint_2">
      <hardwareInterface>hardware_interface/EffortJointInterface</hardwareInterface>
    </joint>
    <actuator name="j2s7s300_joint_2_actuator">
      <hardwareInterface>hardware_interface/EffortJointInterface</hardwareInterface>
      <mechanicalReduction>160</mechanicalReduction>
    </actuator>
  </transmission>
  <link name="j2s7s300_link_3">
    <visual>
      <geometry>
        <mesh filename="package://mobile_base_urdf/model/arm/kinova/meshes/arm_half_2.dae"/>
      </geometry>
      <material name="carbon_fiber">
        <color rgba="0.792156862745098 0.819607843137255 0.933333333333333 1"/>
      </material>
    </visual>
    <visual>
      <geometry>
        <mesh filename="package://mobile_base_urdf/model/arm/kinova/meshes/ring_big.STL"/>
      </geometry>
    </visual>
    <collision>
      <geometry>
        <mesh filename="package://mobile_base_urdf/model/arm/kinova/meshes/arm_half_2.dae"/>
      </geometry>
    </collision>
    <inertial>
      <mass value="0.8447"/>
      <origin xyz="0 0 -0.1022447445"/>
      <inertia ixx="0.00247073761701" ixy="0" ixz="0" iyy="0.00247073761701" iyz="0" izz="0.000380115"/>
    </inertial>
  </link>
  <joint name="j2s7s300_joint_3" type="continuous">
    <parent link="j2s7s300_link_2"/>
    <child link="j2s7s300_link_3"/>
    <axis xyz="0 0 1"/>
    <limit effort="50" lower="-6.28318530718" upper="6.28318530718" velocity="30"/>
    <origin rpy="-1.57079632679489661923 0 0" xyz="0 -0.205 0"/>
    <dynamics damping=".2" friction=".0"/>
  </joint>
  <transmission name="j2s7s300_joint_3_trans">
    <type>transmission_interface/SimpleTransmission</type>
    <joint name="j2s7s300_joint_3">
      <hardwareInterface>hardware_interface/EffortJointInterface</hardwareInterface>
    </joint>
    <actuator name="j2s7s300_joint_3_actuator">
      <hardwareInterface>hardware_interface/EffortJointInterface</hardwareInterface>
      <mechanicalReduction>160</mechanicalReduction>
    </actuator>
  </transmission>
  <link name="j2s7s300_link_4">
    <visual>
      <geometry>
        <mesh filename="package://mobile_base_urdf/model/arm/kinova/meshes/forearm.dae"/>
      </geometry>
      <material name="carbon_fiber">
        <color rgba="0.792156862745098 0.819607843137255 0.933333333333333 1"/>
      </material>
    </visual>
    <visual>
      <geometry>
        <mesh filename="package://mobile_base_urdf/model/arm/kinova/meshes/ring_small.STL"/>
      </geometry>
    </visual>
    <collision>
      <geometry>
        <mesh filename="package://mobile_base_urdf/model/arm/kinova/meshes/forearm.dae"/>
      </geometry>
    </collision>
    <inertial>
      <mass value="0.6763"/>
      <origin xyz="0 0.081 -0.0086"/>
      <inertia ixx="0.00142022431908" ixy="0" ixz="0" iyy="0.000304335" iyz="0" izz="0.00142022431908"/>
    </inertial>
  </link>
  <joint name="j2s7s300_joint_4" type="revolute">
    <parent link="j2s7s300_link_3"/>
    <child link="j2s7s300_link_4"/>
    <axis xyz="0 0 1"/>
    <limit effort="40" lower="0.523598775598" upper="5.75958653158" velocity="30"/>
    <origin rpy="1.57079632679489661923 0 3.14159265358979323846" xyz="0 0 -0.205"/>
    <dynamics damping=".2" friction=".0"/>
  </joint>
  <transmission name="j2s7s300_joint_4_trans">
    <type>transmission_interface/SimpleTransmission</type>
    <joint name="j2s7s300_joint_4">
      <hardwareInterface>hardware_interface/EffortJointInterface</hardwareInterface>
    </joint>
    <actuator name="j2s7s300_joint_4_actuator">
      <hardwareInterface>hardware_interface/EffortJointInterface</hardwareInterface>
      <mechanicalReduction>160</mechanicalReduction>
    </actuator>
  </transmission>
  <link name="j2s7s300_link_5">
    <visual>
      <geometry>
        <mesh filename="package://mobile_base_urdf/model/arm/kinova/meshes/wrist_spherical_1.dae"/>
      </geometry>
      <material name="carbon_fiber">
        <color rgba="0.792156862745098 0.819607843137255 0.933333333333333 1"/>
      </material>
    </visual>
    <visual>
      <geometry>
        <mesh filename="package://mobile_base_urdf/model/arm/kinova/meshes/ring_small.STL"/>
      </geometry>
    </visual>
    <collision>
      <geometry>
        <mesh filename="package://mobile_base_urdf/model/arm/kinova/meshes/wrist_spherical_1.dae"/>
      </geometry>
    </collision>
    <inertial>
      <mass value="0.463"/>
      <origin xyz="0 0.0028848942 -0.0541932613"/>
      <inertia ixx="0.0004321316048" ixy="0" ixz="0" iyy="0.0004321316048" iyz="0" izz="9.26e-05"/>
    </inertial>
  </link>
  <joint name="j2s7s300_joint_5" type="continuous">
    <parent link="j2s7s300_link_4"/>
    <child link="j2s7s300_link_5"/>
    <axis xyz="0 0 1"/>
    <limit effort="30" lower="-6.28318530718" upper="6.28318530718" velocity="30"/>
    <origin rpy="-1.57079632679489661923 0 3.14159265358979323846" xyz="0 0.2073 -0.0114"/>
    <dynamics damping=".2" friction=".0"/>
  </joint>
  <transmission name="j2s7s300_joint_5_trans">
    <type>transmission_interface/SimpleTransmission</type>
    <joint name="j2s7s300_joint_5">
      <hardwareInterface>hardware_interface/EffortJointInterface</hardwareInterface>
    </joint>
    <actuator name="j2s7s300_joint_5_actuator">
      <hardwareInterface>hardware_interface/EffortJointInterface</hardwareInterface>
      <mechanicalReduction>160</mechanicalReduction>
    </actuator>
  </transmission>
  <link name="j2s7s300_link_6">
    <visual>
      <geometry>
        <mesh filename="package://mobile_base_urdf/model/arm/kinova/meshes/wrist_spherical_2.dae"/>
      </geometry>
      <material name="carbon_fiber">
        <color rgba="0.792156862745098 0.819607843137255 0.933333333333333 1"/>
      </material>
    </visual>
    <visual>
      <geometry>
        <mesh filename="package://mobile_base_urdf/model/arm/kinova/meshes/ring_small.STL"/>
      </geometry>
    </visual>
    <collision>
      <geometry>
        <mesh filename="package://mobile_base_urdf/model/arm/kinova/meshes/wrist_spherical_2.dae"/>
      </geometry>
    </collision>
    <inertial>
      <mass value="0.463"/>
      <origin xyz="0 0.0497208855 -0.0028562765"/>
      <inertia ixx="0.0004321316048" ixy="0" ixz="0" iyy="9.26e-05" iyz="0" izz="0.0004321316048"/>
    </inertial>
  </link>
  <joint name="j2s7s300_joint_6" type="revolute">
    <parent link="j2s7s300_link_5"/>
    <child link="j2s7s300_link_6"/>
    <axis xyz="0 0 1"/>
    <limit effort="30" lower="1.1344640138" upper="5.14872129338" velocity="30"/>
    <origin rpy="1.57079632679489661923 0 3.14159265358979323846" xyz="0 0 -0.10375"/>
    <dynamics damping=".2" friction=".0"/>
  </joint>
  <transmission name="j2s7s300_joint_6_trans">
    <type>transmission_interface/SimpleTransmission</type>
    <joint name="j2s7s300_joint_6">
      <hardwareInterface>hardware_interface/EffortJointInterface</hardwareInterface>
    </joint>
    <actuator name="j2s7s300_joint_6_actuator">
      <hardwareInterface>hardware_interface/EffortJointInterface</hardwareInterface>
      <mechanicalReduction>160</mechanicalReduction>
    </actuator>
  </transmission>
  <link name="j2s7s300_link_7">
    <visual>
      <geometry>
        <mesh filename="package://mobile_base_urdf/model/arm/kinova/meshes/hand_3finger.dae"/>
      </geometry>
      <material name="carbon_fiber">
        <color rgba="0.792156862745098 0.819607843137255 0.933333333333333 1"/>
      </material>
    </visual>
    <visual>
      <geometry>
        <mesh filename="package://mobile_base_urdf/model/arm/kinova/meshes/ring_small.STL"/>
      </geometry>
    </visual>
    <collision>
      <geometry>
        <mesh filename="package://mobile_base_urdf/model/arm/kinova/meshes/hand_3finger.dae"/>
      </geometry>
    </collision>
    <inertial>
      <mass value="0.99"/>
      <origin xyz="0 0 -0.06"/>
      <inertia ixx="0.0003453236187" ixy="0" ixz="0" iyy="0.0003453236187" iyz="0" izz="0.0005816"/>
    </inertial>
  </link>
  <joint name="j2s7s300_joint_7" type="continuous">
    <parent link="j2s7s300_link_6"/>
    <child link="j2s7s300_link_7"/>
    <axis xyz="0 0 1"/>
    <limit effort="20" lower="-6.28318530718" upper="6.28318530718" velocity="30"/>
    <origin rpy="-1.57079632679489661923 0 3.14159265358979323846" xyz="0 0.10375 0"/>
    <dynamics damping=".2" friction=".0"/>
  </joint>
  <transmission name="j2s7s300_joint_7_trans">
    <type>transmission_interface/SimpleTransmission</type>
    <joint name="j2s7s300_joint_7">
      <hardwareInterface>hardware_interface/EffortJointInterface</hardwareInterface>
    </joint>
    <actuator name="j2s7s300_joint_7_actuator">
      <hardwareInterface>hardware_interface/EffortJointInterface</hardwareInterface>
      <mechanicalReduction>160</mechanicalReduction>
    </actuator>
  </transmission>
  <link name="j2s7s300_end_effector">
    <visual>
      <origin rpy="-1.57079632679489661923 0 0" xyz="0 0 0"/>
      <geometry>
        <mesh filename="package://mobile_base_urdf/model/base/v3/meshes/Coordinate.STL"/>
      </geometry>
    </visual>
    <inertial>
      <mass value="0.00001"/>
      <origin xyz="0 0 0"/>
      <inertia ixx="0" ixy="0" ixz="0" iyy="0" iyz="0" izz="0"/>
    </inertial>
  </link>
  <joint name="j2s7s300_joint_end_effector" type="fixed">
    <parent link="j2s7s300_link_7"/>
    <child link="j2s7s300_end_effector"/>
    <axis xyz="0 0 1"/>
    <limit effort="0.01" lower="0" upper="0.000001" velocity="0.000001"/>
    <origin rpy="0 1.57079632679489661923 0" xyz="0 0 -0.1600"/>
  </joint>
</robot>
